Workbook

Sheet Dashboard
A1: 🛒 E-COMMERCE SALES ANALYTICS DASHBOARD
X2: Category | Y2: Revenue | Z2: Profit | AB2: Region | AC2: Revenue | AD2: Profit | AF2: Payment | AG2: Revenue | AI2: Year | AJ2: Revenue | AL2: Tier | AM2: Spend | AO2: Churn | AP2: Count | AR2: Segment | AS2: Revenue | AU2: Category | AV2: Stock
X3: Home & Kitchen | Y3: 27721930 | Z3: 11790500 | AB3: East | AC3: 33225560 | AD3: 14109386 | AF3: Cash on Delivery | AG3: 18342180 | AI3: 2022 | AJ3: 6.0209059e+08 | AL3: Platinum | AM3: 78844986 | AO3: High | AP3: 486 | AR3: Consumer | AS3: 33912723 | AU3: Clothing | AV3: 4728
A4: Orders · Product_Master · Customer_Segments · Monthly_KPIs | 2,000 Orders · 70 Products · 1,001 Customers | X4: Electronics | Y4: 26271273 | Z4: 11293622 | AB4: North | AC4: 32398260 | AD4: 13803137 | AF4: Credit Card | AG4: 17606593 | AI4: 2023 | AJ4: 5.9893072e+08 | AL4: Gold | AM4: 19511511 | AO4: Low | AP4: 263 | AR4: Corporate | AS4: 32784494 | AU4: Books | AV4: 4114
X5: Sports & Fitness | Y5: 26037256 | Z5: 11003922 | AB5: South | AC5: 32090536 | AD5: 13635765 | AF5: Debit Card | AG5: 17846309 | AI5: 2024 | AJ5: 6.1960259e+08 | AL5: Silver | AM5: 5380142.1 | AO5: Medium | AP5: 252 | AR5: Home Office | AS5: 32042979 | AU5: Electronics | AV5: 3617
B6: 💰 TOTAL REVENUE | D6: 📦 TOTAL ORDERS | F6: 📈 GROSS PROFIT | H6: 🔄 RETURN RATE | J6: ⭐ AVG RATING | X6: Clothing | Y6: 25348910 | Z6: 10931519 | AB6: West | AC6: 30840014 | AD6: 13189564 | AF6: Digital Wallet | AG6: 19558235 | AL6: Bronze | AM6: 221608.9 | AR6: SMB | AS6: 29814175 | AU6: Home & Kitchen | AV6: 3295
B7: =SUM(Orders!U2:U2001) -> 1.2855437e+08 | D7: =COUNTA(Orders!A2:A2001)-1 -> 1999 | F7: =SUM(Orders!W2:W2001) -> 54737852 | H7: =COUNTIF(Orders!AC2:AC2001,"Yes")/COUNTA(Orders!A2:A2001) -> 0 | J7: =AVERAGE(Orders!AC2:AC2001) -> 2.9184211 | X7: Books | Y7: 23175002 | Z7: 9718289.5 | AF7: EMI | AG7: 19189715 | AU7: Sports & Fitness | AV7: 2813
B8: Orders sheet | D8: Order transactions | F8: Orders sheet | H8: Orders sheet | J8: Customer satisfaction | AF8: Net Banking | AG8: 18581427
AF9: UPI | AG9: 17429912
B11: 👥 UNIQUE CUSTOMERS | D11: 📦 TOTAL PRODUCTS | F11: ⚠ HIGH CHURN RISK | H11: 🏆 BESTSELLERS | J11: 📊 NEW CUSTOMERS
B12: =COUNTA(Customer_Segments!A2:A1002)-1 -> 1000 | D12: =COUNTA(Product_Master!A2:A71)-1 -> 69 | F12: =COUNTIF(Customer_Segments!N2:N1002,"High") -> 486 | H12: =COUNTIF(Product_Master!L2:L71,"Yes") -> 31 | J12: =SUM(Monthly_KPIs!M2:M721) -> 36943
B13: Customer_Segments | D13: Product_Master | F13: Customer_Segments | H13: Product_Master | J13: Monthly_KPIs
B16: ▌ SALES ANALYSIS (Sources: Orders + Monthly_KPIs)
B37: ▌ PAYMENT & TREND ANALYSIS (Sources: Orders + Monthly_KPIs)
B58: ▌ CUSTOMER & PRODUCT ANALYSIS (Sources: Customer_Segments + Product_Master)
B79: ▌ SEGMENT & STOCK SNAPSHOT (Sources: Orders + Product_Master)

Sheet KPI_Calculations
A1: 📈 KPI CALCULATIONS — Formulas Referencing All 4 Raw Data Sheets
A3: KPI Name | B3: Excel Formula | C3: Calculated Value | D3: Source Sheet
A4: ORDERS KPIs — Source: Orders sheet
A5: Total Orders | B5: =COUNTA(Orders!A2:A2001)-1 -> 1999 | C5: =COUNTA(Orders!A2:A2001)-1 -> 1999 | D5: Orders
A6: Total Revenue (INR) | B6: =SUM(Orders!U2:U2001) -> 1.2855437e+08 | C6: =SUM(Orders!U2:U2001) -> 1.2855437e+08 | D6: Orders
A7: Total Gross Profit (INR) | B7: =SUM(Orders!W2:W2001) -> 54737852 | C7: =SUM(Orders!W2:W2001) -> 54737852 | D7: Orders
A8: Avg Order Value (INR) | B8: =AVERAGE(Orders!U2:U2001) -> 64277.185 | C8: =AVERAGE(Orders!U2:U2001) -> 64277.185 | D8: Orders
A9: Avg Profit Margin % | B9: =AVERAGE(Orders!X2:X2001)/100 -> 0.42552375 | C9: =AVERAGE(Orders!X2:X2001)/100 -> 0.42552375 | D9: Orders
A10: Avg Delivery Days | B10: =AVERAGE(Orders!I2:I2001) -> 5.004 | C10: =AVERAGE(Orders!I2:I2001) -> 5.004 | D10: Orders
A11: Total Shipping Cost (INR) | B11: =SUM(Orders!Y2:Y2001) -> 175778 | C11: =SUM(Orders!Y2:Y2001) -> 175778 | D11: Orders
A12: Return Count | B12: =COUNTIF(Orders!AC2:AC2001,"Yes") -> 0 | C12: =COUNTIF(Orders!AC2:AC2001,"Yes") -> 0 | D12: Orders
A13: Return Rate % | B13: =COUNTIF(Orders!AC2:AC2001,"Yes")/COUNTA(Orders!A2:A2001) -> 0 | C13: =COUNTIF(Orders!AC2:AC2001,"Yes")/COUNTA(Orders!A2:A2001) -> 0 | D13: Orders
A14: Avg Customer Rating | B14: =AVERAGE(Orders!AC2:AC2001) -> 2.9184211 | C14: =AVERAGE(Orders!AC2:AC2001) -> 2.9184211 | D14: Orders
A15: PRODUCT KPIs — Source: Product_Master sheet
A16: Total Products in Catalogue | B16: =COUNTA(Product_Master!A2:A71)-1 -> 69 | C16: =COUNTA(Product_Master!A2:A71)-1 -> 69 | D16: Product_Master
A17: Total Stock Units | B17: =SUM(Product_Master!H2:H71) -> 18567 | C17: =SUM(Product_Master!H2:H71) -> 18567 | D17: Product_Master
A18: Avg Product Rating | B18: =AVERAGE(Product_Master!I2:I71) -> 4.1528571 | C18: =AVERAGE(Product_Master!I2:I71) -> 4.1528571 | D18: Product_Master
A19: Avg MRP (INR) | B19: =AVERAGE(Product_Master!F2:F71) -> 24564.374 | C19: =AVERAGE(Product_Master!F2:F71) -> 24564.374 | D19: Product_Master
A20: Avg Cost Price (INR) | B20: =AVERAGE(Product_Master!G2:G71) -> 12876.48 | C20: =AVERAGE(Product_Master!G2:G71) -> 12876.48 | D20: Product_Master
A21: Bestseller Count | B21: =COUNTIF(Product_Master!L2:L71,"Yes") -> 31 | C21: =COUNTIF(Product_Master!L2:L71,"Yes") -> 31 | D21: Product_Master
A22: CUSTOMER KPIs — Source: Customer_Segments sheet
A23: Total Unique Customers | B23: =COUNTA(Customer_Segments!A2:A1002)-1 -> 1000 | C23: =COUNTA(Customer_Segments!A2:A1002)-1 -> 1000 | D23: Customer_Segments
A24: Total Customer Spend (INR) | B24: =SUM(Customer_Segments!G2:G1002) -> 1.0395825e+08 | C24: =SUM(Customer_Segments!G2:G1002) -> 1.0395825e+08 | D24: Customer_Segments
A25: Avg Customer Order Value (INR) | B25: =AVERAGE(Customer_Segments!H2:H1002) -> 14083.683 | C25: =AVERAGE(Customer_Segments!H2:H1002) -> 14083.683 | D25: Customer_Segments
A26: Platinum Tier Customers | B26: =COUNTIF(Customer_Segments!M2:M1002,"Platinum") -> 525 | C26: =COUNTIF(Customer_Segments!M2:M1002,"Platinum") -> 525 | D26: Customer_Segments
A27: High Churn Risk Customers | B27: =COUNTIF(Customer_Segments!N2:N1002,"High") -> 486 | C27: =COUNTIF(Customer_Segments!N2:N1002,"High") -> 486 | D27: Customer_Segments
A28: MONTHLY TREND KPIs — Source: Monthly_KPIs sheet
A29: Total Revenue (Monthly KPIs) | B29: =SUM(Monthly_KPIs!F2:F721) -> 1.8206239e+09 | C29: =SUM(Monthly_KPIs!F2:F721) -> 1.8206239e+09 | D29: Monthly_KPIs
A30: Total Gross Profit (Monthly KPIs) | B30: =SUM(Monthly_KPIs!H2:H721) -> 7.2571967e+08 | C30: =SUM(Monthly_KPIs!H2:H721) -> 7.2571967e+08 | D30: Monthly_KPIs
A31: Total New Customers (All Months) | B31: =SUM(Monthly_KPIs!M2:M721) -> 36943 | C31: =SUM(Monthly_KPIs!M2:M721) -> 36943 | D31: Monthly_KPIs
A32: Total Returns (All Months) | B32: =SUM(Monthly_KPIs!L2:L721) -> 10100.84 | C32: =SUM(Monthly_KPIs!L2:L721) -> 10100.84 | D32: Monthly_KPIs
A33: Avg Monthly Return Rate % | B33: =AVERAGE(Monthly_KPIs!K2:K721)/100 -> 0.14554167 | C33: =AVERAGE(Monthly_KPIs!K2:K721)/100 -> 0.14554167 | D33: Monthly_KPIs

Sheet Pivot_Tables
A1: 📊 PIVOT ANALYSIS — Orders | Product_Master | Customer_Segments | Monthly_KPIs
A3: ▌ FROM: Orders
A5: Revenue & Profit by Category | H5: Revenue & Profit by Region
A6: Category | B6: Sales_Amount_INR | C6: Gross_Profit_INR | D6: Quantity | H6: Region | I6: Sales_Amount_INR | J6: Gross_Profit_INR
A7: Books | B7: 23175002 | C7: 9718289.5 | D7: 1128 | H7: East | I7: 33225560 | J7: 14109386
A8: Clothing | B8: 25348910 | C8: 10931519 | D8: 1192 | H8: North | I8: 32398260 | J8: 13803137
A9: Electronics | B9: 26271273 | C9: 11293622 | D9: 1203 | H9: South | I9: 32090536 | J9: 13635765
A10: Home & Kitchen | B10: 27721930 | C10: 11790500 | D10: 1312 | H10: West | I10: 30840014 | J10: 13189564
A11: Sports & Fitness | B11: 26037256 | C11: 11003922 | D11: 1152 | H11: TOTAL | I11: =SUM(I7:I10) -> 1.2855437e+08 | J11: =SUM(J7:J10) -> 54737852
A12: TOTAL | B12: =SUM(B7:B11) -> 1.2855437e+08 | C12: =SUM(C7:C11) -> 54737852 | D12: =SUM(D7:D11) -> 5987
H13: Revenue by Payment Method
A14: Orders by Customer Segment | H14: Payment_Method | I14: Sales_Amount_INR | J14: Gross_Profit_INR
A15: Customer_Segment | B15: Sales_Amount_INR | C15: Quantity | H15: Cash on Delivery | I15: 18342180 | J15: 7761344.8
A16: Consumer | B16: 33912723 | C16: 1599 | H16: Credit Card | I16: 17606593 | J16: 7495480.2
A17: Corporate | B17: 32784494 | C17: 1485 | H17: Debit Card | I17: 17846309 | J17: 7563946.9
A18: Home Office | B18: 32042979 | C18: 1496 | H18: Digital Wallet | I18: 19558235 | J18: 8453126.3
A19: SMB | B19: 29814175 | C19: 1407 | H19: EMI | I19: 19189715 | J19: 8134982.8
A20: TOTAL | B20: =SUM(B16:B19) -> 1.2855437e+08 | C20: =SUM(C16:C19) -> 5987 | H20: Net Banking | I20: 18581427 | J20: 7820222.2
H21: UPI | I21: 17429912 | J21: 7508748.5
A22: Order Status Breakdown | H22: TOTAL | I22: 1.2855437e+08 | J22: =SUM(J15:J21) -> 54737852
A23: Order_Status | B23: Sales_Amount_INR | C23: Quantity
A24: Cancelled | B24: 12933513 | C24: 592 | H24: Returns Analysis by Category
A25: Delivered | B25: 88486514 | C25: 4145 | H25: Category | I25: Sales_Amount_INR
A26: Processing | B26: 7109221.5 | C26: 334 | H26: Books | I26: 2188264.4
A27: Returned | B27: 8007318.5 | C27: 349 | H27: Clothing | I27: 3154750.5
A28: Shipped | B28: 12017804 | C28: 567 | H28: Electronics | I28: 2516087.8
A29: TOTAL | B29: =SUM(B24:B28) -> 1.2855437e+08 | C29: =SUM(C24:C28) -> 5987 | H29: Home & Kitchen | I29: 3003355.4
H30: Sports & Fitness | I30: 3000840.7
H31: TOTAL | I31: =SUM(I26:I30) -> 13863299
A34: ▌ FROM: Product_Master
A36: Stock & Avg Rating by Category | H36: MRP vs Cost Price by Category
A37: Category | B37: Stock_Units | C37: Avg_Rating | D37: Total_Reviews | H37: Category | I37: MRP_INR | J37: Cost_Price_INR
A38: Books | B38: 274.26667 | C38: 4.36 | D38: 2221.8667 | H38: Books | I38: 22997.669 | J38: 11764.972
A39: Clothing | B39: 315.2 | C39: 4.08 | D39: 2665.4667 | H39: Clothing | I39: 23575.7 | J39: 12291.951
A40: Electronics | B40: 241.13333 | C40: 4.1266667 | D40: 2428.7333 | H40: Electronics | I40: 24934.471 | J40: 13235.553
A41: Home & Kitchen | B41: 219.66667 | C41: 4.1066667 | D41: 2215.0667 | H41: Home & Kitchen | I41: 25207.675 | J41: 13602.933
A42: Sports & Fitness | B42: 281.3 | C42: 4.06 | D42: 2327.7 | H42: Sports & Fitness | I42: 26877.348 | J42: 13792.245
A43: TOTAL | B43: =SUM(B38:B42) -> 1331.5667 | C43: =SUM(C38:C42) -> 20.733333 | D43: =SUM(D38:D42) -> 11858.833 | H43: TOTAL | I43: =SUM(I38:I42) -> 123592.86 | J43: =SUM(J38:J42) -> 64687.654
A46: ▌ FROM: Customer_Segments
A48: Total Spend & Orders by Segment | H48: Churn Risk Distribution by Tier
...

Sheet Data_Cleaning
A1: 🔍 DATA QUALITY REPORT — E-Commerce Sales (All 4 Tables)
A3: Orders (2000 rows × 29 cols) | G3: Product_Master (70 rows × 12 cols) | M3: Customer_Segments (1001 rows × 14 cols) | S3: Monthly_KPIs (720 rows × 13 cols)
A4: Column | B4: Non-Null | C4: Missing | D4: Miss % | E4: Data Type | G4: Column | H4: Non-Null | I4: Missing | J4: Miss % | K4: Data Type | M4: Column | N4: Non-Null | O4: Missing | P4: Miss % | Q4: Data Type | S4: Column | T4: Non-Null | U4: Missing | V4: Miss % | W4: Data Type
A5: Order_ID | B5: 2000 | C5: 0 | D5: 0 | E5: str | G5: Product_ID | H5: 70 | I5: 0 | J5: 0 | K5: str | M5: Customer_ID | N5: 1001 | O5: 0 | P5: 0 | Q5: str | S5: Year | T5: 720 | U5: 0 | V5: 0 | W5: int64
A6: Customer_ID | B6: 2000 | C6: 0 | D6: 0 | E6: str | G6: Product_Name | H6: 70 | I6: 0 | J6: 0 | K6: str | M6: Customer_Name | N6: 1001 | O6: 0 | P6: 0 | Q6: str | S6: Month | T6: 720 | U6: 0 | V6: 0 | W6: str
A7: Customer_Name | B7: 2000 | C7: 0 | D7: 0 | E7: str | G7: Category | H7: 70 | I7: 0 | J7: 0 | K7: str | M7: Segment | N7: 1001 | O7: 0 | P7: 0 | Q7: str | S7: Category | T7: 720 | U7: 0 | V7: 0 | W7: str
A8: Customer_Email | B8: 2000 | C8: 0 | D8: 0 | E8: str | G8: Sub_Category | H8: 70 | I8: 0 | J8: 0 | K8: str | M8: State | N8: 1001 | O8: 0 | P8: 0 | Q8: str | S8: Region | T8: 720 | U8: 0 | V8: 0 | W8: str
A9: Customer_Segment | B9: 2000 | C9: 0 | D9: 0 | E9: str | G9: Brand | H9: 70 | I9: 0 | J9: 0 | K9: str | M9: Region | N9: 1001 | O9: 0 | P9: 0 | Q9: str | S9: Total_Orders | T9: 720 | U9: 0 | V9: 0 | W9: int64
A10: Order_Date | B10: 2000 | C10: 0 | D10: 0 | E10: str | G10: MRP_INR | H10: 70 | I10: 0 | J10: 0 | K10: float64 | M10: Total_Orders | N10: 1001 | O10: 0 | P10: 0 | Q10: int64 | S10: Revenue_INR | T10: 720 | U10: 0 | V10: 0 | W10: float64
A11: Ship_Date | B11: 2000 | C11: 0 | D11: 0 | E11: str | G11: Cost_Price_INR | H11: 70 | I11: 0 | J11: 0 | K11: float64 | M11: Total_Spend_INR | N11: 1001 | O11: 0 | P11: 0 | Q11: float64 | S11: COGS_INR | T11: 720 | U11: 0 | V11: 0 | W11: float64
A12: Delivery_Date | B12: 2000 | C12: 0 | D12: 0 | E12: str | G12: Stock_Units | H12: 70 | I12: 0 | J12: 0 | K12: int64 | M12: Avg_Order_Value | N12: 1001 | O12: 0 | P12: 0 | Q12: float64 | S12: Gross_Profit_INR | T12: 720 | U12: 0 | V12: 0 | W12: float64
A13: Days_to_Deliver | B13: 2000 | C13: 0 | D13: 0 | E13: int64 | G13: Avg_Rating | H13: 70 | I13: 0 | J13: 0 | K13: float64 | M13: Last_Order_Date | N13: 1001 | O13: 0 | P13: 0 | Q13: str | S13: Profit_Margin_Pct | T13: 720 | U13: 0 | V13: 0 | W13: float64
A14: Region | B14: 2000 | C14: 0 | D14: 0 | E14: str | G14: Total_Reviews | H14: 70 | I14: 0 | J14: 0 | K14: int64 | M14: Days_Since_Last_Order | N14: 1001 | O14: 0 | P14: 0 | Q14: int64 | S14: Avg_Order_Value | T14: 720 | U14: 0 | V14: 0 | W14: float64
A15: State | B15: 2000 | C15: 0 | D15: 0 | E15: str | G15: Launch_Date | H15: 70 | I15: 0 | J15: 0 | K15: str | M15: Preferred_Category | N15: 1001 | O15: 0 | P15: 0 | Q15: str | S15: Returns | T15: 720 | U15: 0 | V15: 0 | W15: int64
A16: City | B16: 2000 | C16: 0 | D16: 0 | E16: str | G16: Bestseller | H16: 70 | I16: 0 | J16: 0 | K16: str | M16: Preferred_Payment | N16: 1001 | O16: 0 | P16: 0 | Q16: str | S16: Return_Rate_Pct | T16: 720 | U16: 0 | V16: 0 | W16: float64
A17: Product_ID | B17: 2000 | C17: 0 | D17: 0 | E17: str | M17: Customer_Tier | N17: 1001 | O17: 0 | P17: 0 | Q17: str | S17: New_Customers | T17: 720 | U17: 0 | V17: 0 | W17: int64
A18: Product_Name | B18: 2000 | C18: 0 | D18: 0 | E18: str | M18: Churn_Risk | N18: 1001 | O18: 0 | P18: 0 | Q18: str
A19: Category | B19: 2000 | C19: 0 | D19: 0 | E19: str
A20: Sub_Category | B20: 2000 | C20: 0 | D20: 0 | E20: str
A21: Brand | B21: 2000 | C21: 0 | D21: 0 | E21: str
A22: Quantity | B22: 2000 | C22: 0 | D22: 0 | E22: int64
A23: Unit_Price_INR | B23: 2000 | C23: 0 | D23: 0 | E23: float64
A24: Discount_Pct | B24: 2000 | C24: 0 | D24: 0 | E24: int64
A25: Sales_Amount_INR | B25: 2000 | C25: 0 | D25: 0 | E25: float64
A26: COGS_INR | B26: 2000 | C26: 0 | D26: 0 | E26: float64
A27: Gross_Profit_INR | B27: 2000 | C27: 0 | D27: 0 | E27: float64
A28: Profit_Margin_Pct | B28: 2000 | C28: 0 | D28: 0 | E28: float64
A29: Shipping_Cost_INR | B29: 2000 | C29: 0 | D29: 0 | E29: int64
A30: Payment_Method | B30: 2000 | C30: 0 | D30: 0 | E30: str
... A33: Customer_Rating | B33: 1140 | C33: 860 | D33: 0.43 | E33: float64

Sheet Orders
A1: Order_ID | B1: Customer_ID | C1: Customer_Name | D1: Customer_Email | E1: Customer_Segment | F1: Order_Date | G1: Ship_Date | H1: Delivery_Date | I1: Days_to_Deliver | J1: Region | K1: State | L1: City | M1: Product_ID | N1: Product_Name | O1: Category | P1: Sub_Category | Q1: Brand | R1: Quantity | S1: Unit_Price_INR | T1: Discount_Pct | U1: Sales_Amount_INR | V1: COGS_INR | W1: Gross_Profit_INR | X1: Profit_Margin_Pct | Y1: Shipping_Cost_INR | Z1: Payment_Method | AA1: Order_Status | AB1: Return_Flag | AC1: Customer_Rating
A2: ORD000001 | B2: CUST8557 | C2: Karan Iyer | D2: karan862@email.com | E2: SMB | F2: 2022-07-11 | G2: 2022-07-14 | H2: 2022-07-16 | I2: 2 | J2: East | K2: Odisha | L2: Odisha | M2: PRD2097 | N2: Curtain Set | O2: Home & Kitchen | P2: Decor | Q2: Amazon Basics | R2: 4 | S2: 24506.53 | T2: 10 | U2: 88223.51 | V2: 55785.82 | W2: 32437.69 | X2: 36.77 | Y2: 99 | Z2: EMI | AA2: Delivered | AB2: No | AC2: 2
A3: ORD000002 | B3: CUST5884 | C3: Meena Reddy | D3: meena262@email.com | E3: Corporate | F3: 2022-08-08 | G3: 2022-08-11 | H3: 2022-08-16 | I3: 5 | J3: West | K3: Maharashtra | L3: Mumbai | M3: PRD3376 | N3: Fantasy Epic | O3: Books | P3: Fiction | Q3: Prestige | R3: 5 | S3: 10270.25 | T3: 15 | U3: 43648.56 | V3: 26954.94 | W3: 16693.62 | X3: 38.25 | Y3: 29 | Z3: Digital Wallet | AA3: Delivered | AB3: No | AC3: 3
A4: ORD000003 | B4: CUST2265 | C4: Suresh Kumar | D4: suresh399@email.com | E4: Home Office | F4: 2022-05-07 | G4: 2022-05-10 | H4: 2022-05-15 | I4: 5 | J4: North | K4: Rajasthan | L4: Jodhpur | M4: PRD1231 | N4: USB Cable | O4: Electronics | P4: Accessories | Q4: Wiley | R4: 3 | S4: 19692.77 | T4: 15 | U4: 50216.56 | V4: 25330.64 | W4: 24885.92 | X4: 49.56 | Y4: 0 | Z4: Net Banking | AA4: Delivered | AB4: No | AC4: 2
A5: ORD000004 | B5: CUST7809 | C5: Karan Iyer | D5: karan374@email.com | E5: Corporate | F5: 2024-09-02 | G5: 2024-09-05 | H5: 2024-09-12 | I5: 7 | J5: West | K5: Maharashtra | L5: Pune | M5: PRD2977 | N5: Cricket Bat | O5: Sports & Fitness | P5: Equipment | Q5: Realme | R5: 3 | S5: 38269.13 | T5: 30 | U5: 80365.17 | V5: 40090.39 | W5: 40274.78 | X5: 50.11 | Y5: 199 | Z5: EMI | AA5: Returned | AB5: Yes
A6: ORD000005 | B6: CUST7294 | C6: Nisha Iyer | D6: nisha624@email.com | E6: Consumer | F6: 2022-03-17 | G6: 2022-03-19 | H6: 2022-03-21 | I6: 2 | J6: South | K6: Andhra Pradesh | L6: Andhra Pradesh | M6: PRD2333 | N6: Pre-Workout | O6: Sports & Fitness | P6: Nutrition | Q6: Adidas | R6: 4 | S6: 34863.8 | T6: 10 | U6: 125509.68 | V6: 67792.24 | W6: 57717.44 | X6: 45.99 | Y6: 149 | Z6: Debit Card | AA6: Returned | AB6: Yes
A7: ORD000006 | B7: CUST3565 | C7: Deepak Nair | D7: deepak66@email.com | E7: Corporate | F7: 2022-09-21 | G7: 2022-09-23 | H7: 2022-09-29 | I7: 6 | J7: South | K7: Kerala | L7: Kochi | M7: PRD2779 | N7: Power Bank | O7: Electronics | P7: Accessories | Q7: Prestige | R7: 2 | S7: 10883.7 | T7: 25 | U7: 16325.55 | V7: 10715.17 | W7: 5610.38 | X7: 34.37 | Y7: 29 | Z7: Digital Wallet | AA7: Delivered | AB7: No
A8: ORD000007 | B8: CUST6973 | C8: Vikram Gupta | D8: vikram345@email.com | E8: Corporate | F8: 2024-02-06 | G8: 2024-02-07 | H8: 2024-02-14 | I8: 7 | J8: East | K8: West Bengal | L8: Howrah | M8: PRD1635 | N8: Self-Help Guide | O8: Books | P8: Non-Fiction | Q8: Amazon Basics | R8: 2 | S8: 37105.39 | T8: 0 | U8: 74210.78 | V8: 43159.15 | W8: 31051.63 | X8: 41.84 | Y8: 29 | Z8: Credit Card | AA8: Delivered | AB8: No | AC8: 3
A9: ORD000008 | B9: CUST4859 | C9: Divya Verma | D9: divya366@email.com | E9: Corporate | F9: 2022-11-06 | G9: 2022-11-07 | H9: 2022-11-13 | I9: 6 | J9: East | K9: Bihar | L9: Bihar | M9: PRD3224 | N9: Multivitamin | O9: Sports & Fitness | P9: Nutrition | Q9: Adidas | R9: 1 | S9: 43487.84 | T9: 15 | U9: 36964.66 | V9: 18435.75 | W9: 18528.91 | X9: 50.13 | Y9: 199 | Z9: Digital Wallet | AA9: Shipped | AB9: No
A10: ORD000009 | B10: CUST6897 | C10: Deepak Nair | D10: deepak329@email.com | E10: Consumer | F10: 2024-04-20 | G10: 2024-04-23 | H10: 2024-04-30 | I10: 7 | J10: West | K10: Chhattisgarh | L10: Chhattisgarh | M10: PRD2863 | N10: HP Pavilion | O10: Electronics | P10: Laptops | Q10: Dell | R10: 5 | S10: 32463.47 | T10: 10 | U10: 146085.62 | V10: 83430.39 | W10: 62655.23 | X10: 42.89 | Y10: 29 | Z10: EMI | AA10: Delivered | AB10: No | AC10: 2
A11: ORD000010 | B11: CUST6544 | C11: Anita Kumar | D11: anita556@email.com | E11: Consumer | F11: 2024-09-10 | G11: 2024-09-12 | H11: 2024-09-17 | I11: 5 | J11: South | K11: Andhra Pradesh | L11: Andhra Pradesh | M11: PRD3664 | N11: iPhone 15 | O11: Electronics | P11: Smartphones | Q11: Puma | R11: 3 | S11: 36312.42 | T11: 0 | U11: 108937.26 | V11: 63356.15 | W11: 45581.11 | X11: 41.84 | Y11: 0 | Z11: UPI | AA11: Shipped | AB11: No
A12: ORD000011 | B12: CUST9979 | C12: Aditya Gupta | D12: aditya978@email.com | E12: SMB | F12: 2024-10-04 | G12: 2024-10-06 | H12: 2024-10-10 | I12: 4 | J12: East | K12: Assam | L12: Assam | M12: PRD2543 | N12: Xiaomi 13T | O12: Electronics | P12: Smartphones | Q12: MuscleBlaze | R12: 5 | S12: 44488.12 | T12: 30 | U12: 155708.42 | V12: 86436.36 | W12: 69272.06 | X12: 44.49 | Y12: 149 | Z12: Credit Card | AA12: Delivered | AB12: No | AC12: 4
A13: ORD000012 | B13: CUST3559 | C13: Nisha Patel | D13: nisha813@email.com | E13: SMB | F13: 2024-04-16 | G13: 2024-04-17 | H13: 2024-04-20 | I13: 3 | J13: West | K13: Goa | L13: Goa | M13: PRD4767 | N13: Air Fryer | O13: Home & Kitchen | P13: Appliances | Q13: Realme | R13: 3 | S13: 40871.07 | T13: 15 | U13: 104221.23 | V13: 54103.9 | W13: 50117.33 | X13: 48.09 | Y13: 149 | Z13: Credit Card | AA13: Returned | AB13: Yes
A14: ORD000013 | B14: CUST1142 | C14: Suresh Iyer | D14: suresh328@email.com | E14: Consumer | F14: 2023-05-17 | G14: 2023-05-19 | H14: 2023-05-23 | I14: 4 | J14: North | K14: Rajasthan | L14: Jaipur | M14: PRD2034 | N14: Air Fryer | O14: Home & Kitchen | P14: Appliances | Q14: Realme | R14: 4 | S14: 14543.99 | T14: 20 | U14: 46540.77 | V14: 31252.92 | W14: 15287.85 | X14: 32.85 | Y14: 99 | Z14: Net Banking | AA14: Delivered | AB14: No | AC14: 2
A15: ORD000014 | B15: CUST1263 | C15: Kavya Nair | D15: kavya586@email.com | E15: Home Office | F15: 2024-09-23 | G15: 2024-09-25 | H15: 2024-09-28 | I15: 3 | J15: South | K15: Kerala | L15: Kochi | M15: PRD3378 | N15: Multivitamin | O15: Sports & Fitness | P15: Nutrition | Q15: Nike | R15: 2 | S15: 29778.86 | T15: 10 | U15: 53601.95 | V15: 28883.45 | W15: 24718.5 | X15: 46.11 | Y15: 149 | Z15: UPI | AA15: Returned | AB15: Yes
A16: ORD000015 | B16: CUST6934 | C16: Divya Reddy | D16: divya464@email.com | E16: Consumer | F16: 2024-12-15 | G16: 2024-12-17 | H16: 2024-12-23 | I16: 6 | J16: North | K16: Punjab | L16: Punjab | M16: PRD2002 | N16: CAT Guide | O16: Books | P16: Education | Q16: Nike | R16: 4 | S16: 18273.69 | T16: 20 | U16: 58475.81 | V16: 32764.29 | W16: 25711.52 | X16: 43.97 | Y16: 149 | Z16: UPI | AA16: Delivered | AB16: No | AC16: 5
A17: ORD000016 | B17: CUST3320 | C17: Meena Patel | D17: meena228@email.com | E17: Home Office | F17: 2024-09-07 | G17: 2024-09-09 | H17: 2024-09-14 | I17: 5 | J17: East | K17: Bihar | L17: Bihar | M17: PRD3110 | N17: Whey Protein 1kg | O17: Sports & Fitness | P17: Nutrition | Q17: MuscleBlaze | R17: 4 | S17: 12195.76 | T17: 20 | U17: 39026.43 | V17: 20685.3 | W17: 18341.13 | X17: 47 | Y17: 49 | Z17: Net Banking | AA17: Delivered | AB17: No
A18: ORD000017 | B18: CUST4070 | C18: Karan Patel | D18: karan834@email.com | E18: Consumer | F18: 2024-02-04 | G18: 2024-02-06 | H18: 2024-02-12 | I18: 6 | J18: West | K18: Goa | L18: Goa | M18: PRD3618 | N18: TWS Earbuds | O18: Electronics | P18: Accessories | Q18: MuscleBlaze | R18: 5 | S18: 37809.9 | T18: 30 | U18: 132334.65 | V18: 76725.97 | W18: 55608.68 | X18: 42.02 | Y18: 49 | Z18: Digital Wallet | AA18: Cancelled | AB18: No
A19: ORD000018 | B19: CUST5962 | C19: Nisha Verma | D19: nisha948@email.com | E19: Corporate | F19: 2024-01-17 | G19: 2024-01-19 | H19: 2024-01-21 | I19: 2 | J19: North | K19: Delhi | L19: Noida | M19: PRD2189 | N19: Badminton Racket | O19: Sports & Fitness | P19: Equipment | Q19: HP | R19: 3 | S19: 36984.97 | T19: 15 | U19: 94311.67 | V19: 47865.88 | W19: 46445.79 | X19: 49.25 | Y19: 49 | Z19: Net Banking | AA19: Delivered | AB19: No | AC19: 2
A20: ORD000019 | B20: CUST6140 | C20: Anita Iyer | D20: anita956@email.com | E20: Consumer | F20: 2023-11-20 | G20: 2023-11-21 | H20: 2023-11-24 | I20: 3 | J20: South | K20: Kerala | L20: Kochi | M20: PRD3336 | N20: Track Pants | O20: Clothing | P20: Men | Q20: Realme | R20: 2 | S20: 46889.94 | T20: 0 | U20: 93779.88 | V20: 60365.56 | W20: 33414.32 | X20: 35.63 | Y20: 99 | Z20: Net Banking | AA20: Delivered | AB20: No | AC20: 3
A21: ORD000020 | B21: CUST8619 | C21: Amit Gupta | D21: amit873@email.com | E21: SMB | F21: 2023-10-29 | G21: 2023-11-01 | H21: 2023-11-06 | I21: 5 | J21: South | K21: Andhra Pradesh | L21: Andhra Pradesh | M21: PRD2013 | N21: Fast Charger | O21: Electronics | P21: Accessories | Q21: MuscleBlaze | R21: 1 | S21: 26291.1 | T21: 20 | U21: 21032.88 | V21: 12034.99 | W21: 8997.89 | X21: 42.78 | Y21: 199 | Z21: UPI | AA21: Delivered | AB21: No | AC21: 1
A22: ORD000021 | B22: CUST5789 | C22: Arjun Kumar | D22: arjun285@email.com | E22: Home Office | F22: 2024-10-18 | G22: 2024-10-21 | H22: 2024-10-29 | I22: 8 | J22: West | K22: Madhya Pradesh | L22: Madhya Pradesh | M22: PRD3710 | N22: Yoga Mat | O22: Sports & Fitness | P22: Equipment | Q22: Wiley | R22: 4 | S22: 20625.15 | T22: 20 | U22: 66000.48 | V22: 37942.33 | W22: 28058.15 | X22: 42.51 | Y22: 149 | Z22: UPI | AA22: Delivered | AB22: No | AC22: 5
A23: ORD000022 | B23: CUST9467 | C23: Anita Patel | D23: anita163@email.com | E23: Home Office | F23: 2023-04-19 | G23: 2023-04-22 | H23: 2023-04-25 | I23: 3 | J23: West | K23: Gujarat | L23: Vadodara | M23: PRD2186 | N23: Literary Fiction | O23: Books | P23: Fiction | Q23: MuscleBlaze | R23: 1 | S23: 34329.12 | T23: 0 | U23: 34329.12 | V23: 23421.73 | W23: 10907.39 | X23: 31.77 | Y23: 149 | Z23: Net Banking | AA23: Delivered | AB23: No | AC23: 3
A24: ORD000023 | B24: CUST6172 | C24: Meena Patel | D24: meena567@email.com | E24: Consumer | F24: 2023-10-17 | G24: 2023-10-18 | H24: 2023-10-24 | I24: 6 | J24: South | K24: Karnataka | L24: Mysuru | M24: PRD3935 | N24: Whey Protein 1kg | O24: Sports & Fitness | P24: Nutrition | Q24: Amazon Basics | R24: 3 | S24: 21296.48 | T24: 0 | U24: 63889.44 | V24: 29831.38 | W24: 34058.06 | X24: 53.31 | Y24: 99 | Z24: Cash on Delivery | AA24: Delivered | AB24: No | AC24: 2
A25: ORD000024 | B25: CUST8166 | C25: Pooja Patel | D25: pooja535@email.com | E25: Corporate | F25: 2022-01-05 | G25: 2022-01-07 | H25: 2022-01-10 | I25: 3 | J25: West | K25: Maharashtra | L25: Nashik | M25: PRD4565 | N25: Whey Protein 1kg | O25: Sports & Fitness | P25: Nutrition | Q25: Adidas | R25: 3 | S25: 35606.41 | T25: 30 | U25: 74773.46 | V25: 37395.73 | W25: 37377.73 | X25: 49.99 | Y25: 149 | Z25: Cash on Delivery | AA25: Shipped | AB25: No
A26: ORD000025 | B26: CUST8371 | C26: Sunita Mehta | D26: sunita801@email.com | E26: Consumer | F26: 2023-01-08 | G26: 2023-01-09 | H26: 2023-01-17 | I26: 8 | J26: East | K26: West Bengal | L26: Howrah | M26: PRD4391 | N26: Dell Inspiron | O26: Electronics | P26: Laptops | Q26: Penguin | R26: 2 | S26: 42610.17 | T26: 15 | U26: 72437.29 | V26: 43571.21 | W26: 28866.08 | X26: 39.85 | Y26: 99 | Z26: Credit Card | AA26: Delivered | AB26: No | AC26: 1
A27: ORD000026 | B27: CUST4149 | C27: Karan Kumar | D27: karan580@email.com | E27: Consumer | F27: 2022-12-16 | G27: 2022-12-18 | H27: 2022-12-20 | I27: 2 | J27: West | K27: Chhattisgarh | L27: Chhattisgarh | M27: PRD4395 | N27: Palazzo | O27: Clothing | P27: Women | Q27: MuscleBlaze | R27: 5 | S27: 38556.81 | T27: 0 | U27: 192784.05 | V27: 100671.13 | W27: 92112.92 | X27: 47.78 | Y27: 199 | Z27: Cash on Delivery | AA27: Delivered | AB27: No | AC27: 3
A28: ORD000027 | B28: CUST7779 | C28: Kavya Reddy | D28: kavya48@email.com | E28: SMB | F28: 2022-09-11 | G28: 2022-09-13 | H28: 2022-09-18 | I28: 5 | J28: East | K28: Assam | L28: Assam | M28: PRD2944 | N28: MacBook Air | O28: Electronics | P28: Laptops | Q28: HP | R28: 5 | S28: 10249.22 | T28: 30 | U28: 35872.27 | V28: 19954.41 | W28: 15917.86 | X28: 44.37 | Y28: 149 | Z28: Net Banking | AA28: Delivered | AB28: No | AC28: 5
A29: ORD000028 | B29: CUST6377 | C29: Manish Kumar | D29: manish705@email.com | E29: Consumer | F29: 2024-06-24 | G29: 2024-06-26 | H29: 2024-07-03 | I29: 7 | J29: East | K29: Bihar | L29: Bihar | M29: PRD1105 | N29: Fantasy Epic | O29: Books | P29: Fiction | Q29: HP | R29: 1 | S29: 40553.65 | T29: 10 | U29: 36498.29 | V29: 25032.73 | W29: 11465.56 | X29: 31.41 | Y29: 199 | Z29: EMI | AA29: Delivered | AB29: No | AC29: 1
A30: ORD000029 | B30: CUST2403 | C30: Suresh Kumar | D30: suresh379@email.com | E30: Consumer | F30: 2022-11-02 | G30: 2022-11-03 | H30: 2022-11-09 | I30: 6 | J30: East | K30: Bihar | L30: Bihar | M30: PRD4232 | N30: Formal Shirt | O30: Clothing | P30: Men | Q30: Adidas | R30: 5 | S30: 14633.46 | T30: 10 | U30: 65850.57 | V30: 42542.54 | W30: 23308.03 | X30: 35.4 | Y30: 199 | Z30: Net Banking | AA30: Delivered | AB30: No | AC30: 2
A31: ORD000030 | B31: CUST5661 | C31: Kavya Sharma | D31: kavya18@email.com | E31: Home Office | F31: 2022-06-26 | G31: 2022-06-28 | H31: 2022-07-05 | I31: 7 | J31: East | K31: Assam | L31: Assam | M31: PRD2804 | N31: Asus VivoBook | O31: Electronics | P31: Laptops | Q31: Samsung | R31: 5 | S31: 33572.29 | T31: 15 | U31: 142682.23 | V31: 91549.44 | W31: 51132.79 | X31: 35.84 | Y31: 0 | Z31: EMI | AA31: Delivered | AB31: No | AC31: 1
A32: ORD000031 | B32: CUST1608 | C32: Nisha Iyer | D32: nisha950@email.com | E32: SMB | F32: 2022-09-24 | G32: 2022-09-27 | H32: 2022-10-02 | I32: 5 | J32: East | K32: West Bengal | L32: Kolkata | M32: PRD2270 | N32: Lenovo IdeaPad | O32: Electronics | P32: Laptops | Q32: Puma | R32: 3 | S32: 1744.14 | T32: 25 | U32: 3924.32 | V32: 2309.2 | W32: 1615.12 | X32: 41.16 | Y32: 29 | Z32: Cash on Delivery | AA32: Delivered | AB32: No | AC32: 5
A33: ORD000032 | B33: CUST6944 | C33: Amit Patel | D33: amit334@email.com | E33: Consumer | F33: 2024-03-17 | G33: 2024-03-18 | H33: 2024-03-24 | I33: 6 | J33: East | K33: Assam | L33: Assam | M33: PRD2984 | N33: Bookshelf | O33: Home & Kitchen | P33: Furniture | Q33: Amazon Basics | R33: 5 | S33: 47274.41 | T33: 25 | U33: 177279.04 | V33: 89759.23 | W33: 87519.81 | X33: 49.37 | Y33: 199 | Z33: UPI | AA33: Delivered | AB33: No | AC33: 2
A34: ORD000033 | B34: CUST6848 | C34: Rahul Kumar | D34: rahul217@email.com | E34: Consumer | F34: 2024-04-13 | G34: 2024-04-15 | H34: 2024-04-22 | I34: 7 | J34: South | K34: Tamil Nadu | L34: Coimbatore | M34: PRD2119 | N34: HP Pavilion | O34: Electronics | P34: Laptops | Q34: HP | R34: 3 | S34: 32362.85 | T34: 30 | U34: 67961.98 | V34: 43893.72 | W34: 24068.26 | X34: 35.41 | Y34: 199 | Z34: EMI | AA34: Delivered | AB34: No | AC34: 2
A35: ORD000034 | B35: CUST7520 | C35: Nisha Mehta | D35: nisha993@email.com | E35: SMB | F35: 2024-10-25 | G35: 2024-10-27 | H35: 2024-10-30 | I35: 3 | J35: West | K35: Madhya Pradesh | L35: Madhya Pradesh | M35: PRD4929 | N35: Microwave | O35: Home & Kitchen | P35: Appliances | Q35: Samsung | R35: 5 | S35: 18855.16 | T35: 25 | U35: 70706.85 | V35: 39552.18 | W35: 31154.67 | X35: 44.06 | Y35: 149 | Z35: Cash on Delivery | AA35: Delivered | AB35: No
A36: ORD000035 | B36: CUST7057 | C36: Kavya Nair | D36: kavya450@email.com | E36: Corporate | F36: 2024-01-18 | G36: 2024-01-19 | H36: 2024-01-21 | I36: 2 | J36: North | K36: Uttar Pradesh | L36: Lucknow | M36: PRD1457 | N36: Flip Flops | O36: Clothing | P36: Footwear | Q36: HP | R36: 4 | S36: 30156.77 | T36: 25 | U36: 90470.31 | V36: 44797.12 | W36: 45673.19 | X36: 50.48 | Y36: 0 | Z36: Credit Card | AA36: Delivered | AB36: No | AC36: 1
A37: ORD000036 | B37: CUST5589 | C37: Manish Gupta | D37: manish373@email.com | E37: Consumer | F37: 2023-12-28 | G37: 2023-12-30 | H37: 2024-01-07 | I37: 8 | J37: East | K37: Odisha | L37: Odisha | M37: PRD3274 | N37: Realme 11 | O37: Electronics | P37: Smartphones | Q37: Nike | R37: 5 | S37: 25053.9 | T37: 15 | U37: 106479.07 | V37: 52499.91 | W37: 53979.16 | X37: 50.69 | Y37: 29 | Z37: UPI | AA37: Shipped | AB37: No
A38: ORD000037 | B38: CUST8336 | C38: Deepak Singh | D38: deepak90@email.com | E38: SMB | F38: 2023-07-23 | G38: 2023-07-24 | H38: 2023-07-29 | I38: 5 | J38: West | K38: Maharashtra | L38: Pune | M38: PRD2363 | N38: Casual Sneakers | O38: Clothing | P38: Footwear | Q38: Apple | R38: 3 | S38: 38711.63 | T38: 0 | U38: 116134.89 | V38: 79344.42 | W38: 36790.47 | X38: 31.68 | Y38: 0 | Z38: UPI | AA38: Cancelled | AB38: No
A39: ORD000038 | B39: CUST2876 | C39: Anita Singh | D39: anita856@email.com | E39: Corporate | F39: 2022-10-21 | G39: 2022-10-24 | H39: 2022-11-01 | I39: 8 | J39: East | K39: Bihar | L39: Bihar | M39: PRD4817 | N39: Induction Cooktop | O39: Home & Kitchen | P39: Appliances | Q39: HP | R39: 3 | S39: 48428.86 | T39: 25 | U39: 108964.94 | V39: 67002.49 | W39: 41962.45 | X39: 38.51 | Y39: 199 | Z39: EMI | AA39: Delivered | AB39: No
A40: ORD000039 | B40: CUST8786 | C40: Rohit Singh | D40: rohit687@email.com | E40: SMB | F40: 2023-01-29 | G40: 2023-01-31 | H40: 2023-02-03 | I40: 3 | J40: West | K40: Chhattisgarh | L40: Chhattisgarh | M40: PRD1009 | N40: Artificial Plant | O40: Home & Kitchen | P40: Decor | Q40: Adidas | R40: 4 | S40: 6795.1 | T40: 20 | U40: 21744.32 | V40: 10814.27 | W40: 10930.05 | X40: 50.27 | Y40: 149 | Z40: EMI | AA40: Delivered | AB40: No | AC40: 1
...

Sheet Product_Master
A1: Product_ID | B1: Product_Name | C1: Category | D1: Sub_Category | E1: Brand | F1: MRP_INR | G1: Cost_Price_INR | H1: Stock_Units | I1: Avg_Rating | J1: Total_Reviews | K1: Launch_Date | L1: Bestseller
A2: PRD1001 | B2: iPhone 15 | C2: Electronics | D2: Smartphones | E2: Apple | F2: 45664.21 | G2: 27979.28 | H2: 422 | I2: 3.6 | J2: 170 | K2: 2020-07-08 | L2: Yes
A3: PRD1002 | B3: Samsung S24 | C3: Electronics | D3: Smartphones | E3: OnePlus | F3: 21029 | G3: 11392.32 | H3: 491 | I3: 3.4 | J3: 976 | K3: 2023-01-07 | L3: No
A4: PRD1003 | B4: OnePlus 12 | C4: Electronics | D4: Smartphones | E4: MuscleBlaze | F4: 5633.99 | G4: 2646.66 | H4: 237 | I4: 5 | J4: 1725 | K4: 2023-06-08 | L4: Yes
A5: PRD1004 | B5: Realme 11 | C5: Electronics | D5: Smartphones | E5: Adidas | F5: 4608.48 | G5: 2205.84 | H5: 29 | I5: 3.7 | J5: 3681 | K5: 2022-02-18 | L5: Yes
A6: PRD1005 | B6: Xiaomi 13T | C6: Electronics | D6: Smartphones | E6: Wiley | F6: 42162.28 | G6: 19766.67 | H6: 337 | I6: 4.7 | J6: 1206 | K6: 2022-04-19 | L6: No
A7: PRD1006 | B7: Dell Inspiron | C7: Electronics | D7: Laptops | E7: Philips | F7: 41704.04 | G7: 20761.42 | H7: 317 | I7: 4.3 | J7: 4685 | K7: 2018-09-13 | L7: Yes
A8: PRD1007 | B8: HP Pavilion | C8: Electronics | D8: Laptops | E8: Samsung | F8: 13750.78 | G8: 8691.55 | H8: 143 | I8: 4.9 | J8: 1168 | K8: 2022-01-15 | L8: Yes
A9: PRD1008 | B9: Lenovo IdeaPad | C9: Electronics | D9: Laptops | E9: Samsung | F9: 6469.24 | G9: 2861.15 | H9: 21 | I9: 4.2 | J9: 2189 | K9: 2018-06-17 | L9: Yes
A10: PRD1009 | B10: Asus VivoBook | C10: Electronics | D10: Laptops | E10: HP | F10: 46462.44 | G10: 27897.76 | H10: 64 | I10: 4.6 | J10: 4913 | K10: 2020-08-16 | L10: No
A11: PRD1010 | B11: MacBook Air | C11: Electronics | D11: Laptops | E11: Nike | F11: 23718.11 | G11: 11243.58 | H11: 127 | I11: 4.4 | J11: 1725 | K11: 2023-06-11 | L11: Yes
A12: PRD1011 | B12: TWS Earbuds | C12: Electronics | D12: Accessories | E12: Wiley | F12: 10158.95 | G12: 4969.61 | H12: 92 | I12: 3.2 | J12: 1429 | K12: 2021-07-18 | L12: No
A13: PRD1012 | B13: Power Bank | C13: Electronics | D13: Accessories | E13: Amazon Basics | F13: 13767.52 | G13: 8584.41 | H13: 352 | I13: 3.6 | J13: 2733 | K13: 2020-01-26 | L13: Yes
... A71: PRD1070 | B71: Multivitamin | C71: Sports & Fitness | D71: Nutrition | E71: HP | F71: 44164.88 | G71: 18083.3 | H71: 255 | I71: 4.6 | J71: 389 | K71: 2020-12-26 | L71: No

Sheet Customer_Segments
A1: Customer_ID | B1: Customer_Name | C1: Segment | D1: State | E1: Region | F1: Total_Orders | G1: Total_Spend_INR | H1: Avg_Order_Value | I1: Last_Order_Date | J1: Days_Since_Last_Order | K1: Preferred_Category | L1: Preferred_Payment | M1: Customer_Tier | N1: Churn_Risk
A2: CUST1000 | B2: Rahul Kumar | C2: SMB | D2: Bihar | E2: East | F2: 19 | G2: 16791.5 | H2: 883.76 | I2: 2024-07-27 | J2: 158 | K2: Clothing | L2: UPI | M2: Silver | N2: Medium
A3: CUST1001 | B3: Amit Singh | C3: Corporate | D3: Goa | E3: West | F3: 21 | G3: 106805.35 | H3: 5085.97 | I3: 2024-10-27 | J3: 66 | K3: Clothing | L3: EMI | M3: Platinum | N3: Low
A4: CUST1002 | B4: Arjun Singh | C4: Corporate | D4: West Bengal | E4: East | F4: 1 | G4: 192592.59 | H4: 192592.59 | I4: 2024-10-31 | J4: 62 | K4: Books | L4: Debit Card | M4: Platinum | N4: Low
A5: CUST1003 | B5: Divya Singh | C5: Home Office | D5: Maharashtra | E5: West | F5: 27 | G5: 177088.19 | H5: 6558.82 | I5: 2024-06-21 | J5: 194 | K5: Home & Kitchen | L5: EMI | M5: Platinum | N5: High
A6: CUST1004 | B6: Rohit Nair | C6: Home Office | D6: Tamil Nadu | E6: South | F6: 7 | G6: 172078.73 | H6: 24582.68 | I6: 2024-01-05 | J6: 362 | K6: Clothing | L6: Digital Wallet | M6: Platinum | N6: High
A7: CUST1005 | B7: Manish Verma | C7: Corporate | D7: Gujarat | E7: West | F7: 19 | G7: 135455.74 | H7: 7129.25 | I7: 2024-10-23 | J7: 70 | K7: Electronics | L7: Digital Wallet | M7: Platinum | N7: Low
A8: CUST1006 | B8: Priya Nair | C8: Consumer | D8: Andhra Pradesh | E8: South | F8: 23 | G8: 115921.46 | H8: 5040.06 | I8: 2024-10-20 | J8: 73 | K8: Books | L8: EMI | M8: Platinum | N8: Low
A9: CUST1007 | B9: Rahul Mehta | C9: Corporate | D9: Bihar | E9: East | F9: 18 | G9: 147221.56 | H9: 8178.98 | I9: 2024-02-27 | J9: 309 | K9: Books | L9: Debit Card | M9: Platinum | N9: High
A10: CUST1008 | B10: Divya Reddy | C10: Home Office | D10: Rajasthan | E10: North | F10: 9 | G10: 17304.37 | H10: 1922.71 | I10: 2024-04-03 | J10: 273 | K10: Books | L10: Credit Card | M10: Silver | N10: High
A11: CUST1009 | B11: Manish Singh | C11: Home Office | D11: Gujarat | E11: West | F11: 7 | G11: 7187.22 | H11: 1026.75 | I11: 2024-04-10 | J11: 266 | K11: Sports & Fitness | L11: EMI | M11: Bronze | N11: High
A12: CUST1010 | B12: Manish Verma | C12: Consumer | D12: Rajasthan | E12: North | F12: 22 | G12: 147761.77 | H12: 6716.44 | I12: 2024-05-20 | J12: 226 | K12: Sports & Fitness | L12: Cash on Delivery | M12: Platinum | N12: High
A13: CUST1011 | B13: Manish Singh | C13: SMB | D13: Kerala | E13: South | F13: 28 | G13: 82495.61 | H13: 2946.27 | I13: 2024-12-29 | J13: 3 | K13: Electronics | L13: Debit Card | M13: Gold | N13: Low
... A1002: CUST2000 | B1002: Rekha Verma | C1002: Consumer | D1002: Karnataka | E1002: South | F1002: 27 | G1002: 180236.61 | H1002: 6675.43 | I1002: 2024-08-26 | J1002: 128 | K1002: Home & Kitchen | L1002: Debit Card | M1002: Platinum | N1002: Medium

Sheet Monthly_KPIs
A1: Year | B1: Month | C1: Category | D1: Region | E1: Total_Orders | F1: Revenue_INR | G1: COGS_INR | H1: Gross_Profit_INR | I1: Profit_Margin_Pct | J1: Avg_Order_Value | K1: Returns | L1: Return_Rate_Pct | M1: New_Customers
A2: 2022 | B2: 2022-01 | C2: Electronics | D2: North | E2: 207 | F2: 97798.16 | G2: 56935.87 | H2: 40862.29 | I2: 41.78 | J2: 472.45 | K2: 22 | L2: 10.63 | M2: 44
A3: 2022 | B3: 2022-01 | C3: Electronics | D3: South | E3: 101 | F3: 131045.36 | G3: 72854.2 | H3: 58191.16 | I3: 44.41 | J3: 1297.48 | K3: 13 | L3: 12.87 | M3: 43
A4: 2022 | B4: 2022-01 | C4: Electronics | D4: East | E4: 99 | F4: 2638714.6 | G4: 1795840.1 | H4: 842874.56 | I4: 31.94 | J4: 26653.68 | K4: 18 | L4: 18.18 | M4: 52
A5: 2022 | B5: 2022-01 | C5: Electronics | D5: West | E5: 93 | F5: 3540125 | G5: 1887164.7 | H5: 1652960.3 | I5: 46.69 | J5: 38065.86 | K5: 30 | L5: 32.26 | M5: 91
A6: 2022 | B6: 2022-01 | C6: Clothing | D6: North | E6: 115 | F6: 4759961.6 | G6: 2652446.6 | H6: 2107515 | I6: 44.28 | J6: 41390.97 | K6: 4 | L6: 3.48 | M6: 93
A7: 2022 | B7: 2022-01 | C7: Clothing | D7: South | E7: 46 | F7: 3937638.6 | G7: 2695247.4 | H7: 1242391.2 | I7: 31.55 | J7: 85600.84 | K7: 0 | L7: 0 | M7: 42
A8: 2022 | B8: 2022-01 | C8: Clothing | D8: East | E8: 98 | F8: 3333311.2 | G8: 1898593.2 | H8: 1434718.1 | I8: 43.04 | J8: 34013.38 | K8: 22 | L8: 22.45 | M8: 42
A9: 2022 | B9: 2022-01 | C9: Clothing | D9: West | E9: 139 | F9: 921735.6 | G9: 571433.58 | H9: 350302.02 | I9: 38 | J9: 6631.19 | K9: 2 | L9: 1.44 | M9: 29
A10: 2022 | B10: 2022-01 | C10: Home & Kitchen | D10: North | E10: 264 | F10: 4327755.1 | G10: 2196400 | H10: 2131355.2 | I10: 49.25 | J10: 16393.01 | K10: 15 | L10: 5.68 | M10: 22
A11: 2022 | B11: 2022-01 | C11: Home & Kitchen | D11: South | E11: 99 | F11: 1412723.1 | G11: 737233.14 | H11: 675489.94 | I11: 47.81 | J11: 14269.93 | K11: 8 | L11: 8.08 | M11: 56
A12: 2022 | B12: 2022-01 | C12: Home & Kitchen | D12: East | E12: 133 | F12: 981158.01 | G12: 684601.21 | H12: 296556.8 | I12: 30.23 | J12: 7377.13 | K12: 16 | L12: 12.03 | M12: 75
A13: 2022 | B13: 2022-01 | C13: Home & Kitchen | D13: West | E13: 164 | F13: 1637947 | G13: 1023540 | H13: 614407.06 | I13: 37.51 | J13: 9987.48 | K13: 0 | L13: 0 | M13: 46
... A721: 2024 | B721: 2024-12 | C721: Sports & Fitness | D721: West | E721: 180 | F721: 1554046 | G721: 995301.65 | H721: 558744.36 | I721: 35.95 | J721: 8633.59 | K721: 23 | L721: 12.78 | M721: 33
